Workbook

Sheet Data Kualitas Udara
A1: DATA KUALITAS UDARA SENSING SATELIT (SENTINEL-5P)
A2: Lokasi: Telukdalam / Desa Mendenrejo | Periode: 30 Agustus 2025 - 30 Agustus 2026
A4: DATE_TIME | B4: CO | C4: NO2 | D4: SO2 | E4: CH4
A5: 2025-08-30
A6: 2025-08-31 | D6: 7.3868259e-06
A7: 2025-09-01
A8: 2025-09-02 | D8: -0.0002346663
A9: 2025-09-03
A10: 2025-09-04
A11: 2025-09-05
A12: 2025-09-06 | B12: 0.026540564 | C12: 1.0304032e-05 | D12: 0.00019491291
A13: 2025-09-07
A14: 2025-09-08 | D14: 6.8523207e-07
A15: 2025-09-09 | D15: 1.2973645e-05
A16: 2025-09-10
A17: 2025-09-11
A18: 2025-09-12 | B18: 0.025727846
A19: 2025-09-13
A20: 2025-09-14
A21: 2025-09-15 | B21: 0.025775127 | D21: -7.0239825e-05
A22: 2025-09-16 | C22: 1.2860852e-05 | D22: 0.00019060512
A23: 2025-09-17 | C23: 1.2881493e-05 | D23: 6.4482607e-05
A24: 2025-09-18 | C24: 1.8448739e-06 | D24: -4.8769914e-05
A25: 2025-09-19
A26: 2025-09-20 | D26: 4.2855634e-05
A27: 2025-09-21 | B27: 0.029569078
A28: 2025-09-22 | D28: 7.22322e-05
A29: 2025-09-23 | B29: 0.036876753 | C29: -2.1327718e-07 | D29: -9.2418404e-06
A30: 2025-09-24
A31: 2025-09-25 | D31: -0.00016114056
A32: 2025-09-26 | B32: 0.027287951 | C32: 1.8000708e-06 | D32: -1.5314985e-05
A33: 2025-09-27 | B33: 0.023317775
A34: 2025-09-28
A35: 2025-09-29
A36: 2025-09-30 | B36: 0.031431433 | C36: 5.9585932e-06 | D36: 4.6155408e-05
A37: 2025-10-01 | C37: -2.9038224e-08 | D37: 2.9692177e-05
A38: 2025-10-02 | B38: 0.024853827 | C38: -4.3908144e-06 | D38: -0.00012306761
A39: 2025-10-03
A40: 2025-10-04
A41: 2025-10-05 | C41: 2.6188877e-06 | D41: 0.0001151385
...

Sheet Ringkasan & Statistik
A1: RINGKASAN & STATISTIK DATA KUALITAS UDARA
A2: Metrik Statistik Data Satelit Sentinel-5P Telukdalam
A4: Ringkasan Parameter Polutan
A5: Parameter | B5: Jumlah Data Valid | C5: Jumlah Missing (NaN) | D5: Mean (Rata-rata) | E5: Min | F5: Max | G5: Median
A6: CO | B6: =COUNT('Data Kualitas Udara'!B5:B370) | C6: =COUNTBLANK('Data Kualitas Udara'!B5:B370) | D6: =AVERAGE('Data Kualitas Udara'!B5:B370) | E6: =MIN('Data Kualitas Udara'!B5:B370) | F6: =MAX('Data Kualitas Udara'!B5:B370) | G6: =MEDIAN('Data Kualitas Udara'!B5:B370)
A7: NO2 | B7: =COUNT('Data Kualitas Udara'!C5:C370) | C7: =COUNTBLANK('Data Kualitas Udara'!C5:C370) | D7: =AVERAGE('Data Kualitas Udara'!C5:C370) | E7: =MIN('Data Kualitas Udara'!C5:C370) | F7: =MAX('Data Kualitas Udara'!C5:C370) | G7: =MEDIAN('Data Kualitas Udara'!C5:C370)
A8: SO2 | B8: =COUNT('Data Kualitas Udara'!D5:D370) | C8: =COUNTBLANK('Data Kualitas Udara'!D5:D370) | D8: =AVERAGE('Data Kualitas Udara'!D5:D370) | E8: =MIN('Data Kualitas Udara'!D5:D370) | F8: =MAX('Data Kualitas Udara'!D5:D370) | G8: =MEDIAN('Data Kualitas Udara'!D5:D370)
A9: CH4 | B9: =COUNT('Data Kualitas Udara'!E5:E370) | C9: =COUNTBLANK('Data Kualitas Udara'!E5:E370) | D9: =AVERAGE('Data Kualitas Udara'!E5:E370) | E9: =MIN('Data Kualitas Udara'!E5:E370) | F9: =MAX('Data Kualitas Udara'!E5:E370) | G9: =MEDIAN('Data Kualitas Udara'!E5:E370)
